Workbook
Name \: {"Book1","4.09 FLORA DAN FAUNA.xls","4.22 PERLENGKAPAN SEKOLAH.xls"}
Name \0: #REF!
Name \A: #REF!
Name \a1: #REF!
Name \B: #REF!
Name \c: #REF!
Name \d: #REF!
Name \e: #REF!
Name \E1: #REF!
Name \f: #REF!
Name \g: #REF!
Name \h: #REF!
Name \I: #REF!
Name \J: #REF!
Name \K: #REF!
Name \L: #REF!
Name \M: #REF!
Name \N: #REF!
Name \O: #REF!
Name \P: #REF!
Name \Q: #REF!
Name \R: #REF!
Name \RESUME: #REF!
Name \RESUME1: #REF!
Name \S: #REF!
Name \T: #REF!
Name \u: #REF!
Name \v: #REF!
Name \w: #REF!
Name \WQ: '[1]BAG-2'!#REF!
Name \x: #REF!
Name \y: #REF!
Name \z: #REF!
Name _: #REF!
Name _.90: #REF!
Name _\0: #REF!
Name _\A: #REF!
Name _\b: #REF!
Name _\c: #N/A
Name _\d: #REF!
Name _\E: #REF!
Name _\E1: #REF!
Name _\F: #REF!
Name _\G: #REF!
Name _\H: #REF!
Name _\I: #REF!
Name _\J: #REF!
Name _\K: #REF!
Name _\L: #REF!
Name _\M: #REF!
Name _\N: #REF!
Name _\O: #REF!
Name _\P: #REF!
Name _\Q: #REF!
Name _\R: #REF!
Name _\S: #REF!
Name _\T: #REF!
Name _\U: #REF!
Name _\V: #REF!
Name _\W: #REF!

Sheet Backup Galian (2)
C2: BACK UP GALIAN | O2: BACK UP STRIPING
C4: Pekerjaan : | D4: Galian tanah menggunakan alat berat (secara mekanis) | O4: Pekerjaan : | P4: Striping, penghamparan dan pemadatan badan tanggul tanah
C5: Satuan : | D5: M3 | O5: Satuan : | P5: M3
I7: Luas Galian/Timbunan : | R7: Luas Galian/Timbunan :
I8: tinggi eksisting (h' )= | J8: 2.5 | R8: Tinggi (h) = | S8: 0.1
I9: Lebar (b1) = | J9: 25 | R9: Lebar (b) = | S9: 10
I10: Lebar (b2) = | J10: 16
I11: tinggi galian (h) = | J11: 2.5
C15: STA | D15: Jarak | E15: h' (m) | F15: b1 (m) | G15: b2 (m) | H15: h (m) | I15: Luasan (m2) | J15: Volume (m3) | O15: STA | P15: Jarak | Q15: h (m) | R15: b (m) | S15: Luasan (m2) | T15: Volume (m3)
C16: 0 | O16: 0
D17: =C18-C16 -> 25 | E17: =$J$8 -> 2.5 | F17: =$J$9 -> 25 | G17: =$J$10 -> 16 | H17: =$J$11 -> 2.5 | I17: =0.5*((F17+G17)*H17) -> 51.25 | J17: =I17*D17 -> 1281.25 | P17: =O18-O16 -> 25 | Q17: =$S$8 -> 0.1 | R17: =$S$9 -> 10 | S17: =Q17*R17 -> 1 | T17: =S17*P17 -> 25
C18: =+C16+25 -> 25 | O18: =+O16+25 -> 25
D19: =C20-C18 -> 25 | E19: =$J$8 -> 2.5 | F19: =$J$9 -> 25 | G19: =$J$10 -> 16 | H19: =$J$11 -> 2.5 | I19: =0.5*((F19+G19)*H19) -> 51.25 | J19: =I19*D19 -> 1281.25 | P19: =O20-O18 -> 25 | Q19: =$S$8 -> 0.1 | R19: =$S$9 -> 10 | S19: =Q19*R19 -> 1 | T19: =S19*P19 -> 25
C20: =+C18+25 -> 50 | O20: =+O18+25 -> 50
D21: =C22-C20 -> 25 | E21: =$J$8 -> 2.5 | F21: =$J$9 -> 25 | G21: =$J$10 -> 16 | H21: =$J$11 -> 2.5 | I21: =0.5*((F21+G21)*H21) -> 51.25 | J21: =I21*D21 -> 1281.25 | P21: =O22-O20 -> 25 | Q21: =$S$8 -> 0.1 | R21: =$S$9 -> 10 | S21: =Q21*R21 -> 1 | T21: =S21*P21 -> 25
C22: =+C20+25 -> 75 | O22: =+O20+25 -> 75
D23: =C24-C22 -> 25 | E23: =$J$8 -> 2.5 | F23: =$J$9 -> 25 | G23: =$J$10 -> 16 | H23: =$J$11 -> 2.5 | I23: =0.5*((F23+G23)*H23) -> 51.25 | J23: =I23*D23 -> 1281.25 | P23: =O24-O22 -> 25 | Q23: =$S$8 -> 0.1 | R23: =$S$9 -> 10 | S23: =Q23*R23 -> 1 | T23: =S23*P23 -> 25
C24: =+C22+25 -> 100 | O24: =+O22+25 -> 100
D25: =C26-C24 -> 25 | E25: =$J$8 -> 2.5 | F25: =$J$9 -> 25 | G25: =$J$10 -> 16 | H25: =$J$11 -> 2.5 | I25: =0.5*((F25+G25)*H25) -> 51.25 | J25: =I25*D25 -> 1281.25 | P25: =O26-O24 -> 25 | Q25: =$S$8 -> 0.1 | R25: =$S$9 -> 10 | S25: =Q25*R25 -> 1 | T25: =S25*P25 -> 25
C26: =+C24+25 -> 125 | O26: =+O24+25 -> 125
D27: =C28-C26 -> 25 | E27: =$J$8 -> 2.5 | F27: =$J$9 -> 25 | G27: =$J$10 -> 16 | H27: =$J$11+$J$8 -> 5 | I27: =0.5*((F27+G27)*H27) -> 102.5 | J27: =I27*D27 -> 2562.5 | P27: =O28-O26 -> 25 | Q27: =$S$8 -> 0.1 | R27: =$S$9 -> 10 | S27: =Q27*R27 -> 1 | T27: =S27*P27 -> 25
C28: =+C26+25 -> 150 | O28: =+O26+25 -> 150
D29: =C30-C28 -> 25 | E29: =$J$8 -> 2.5 | F29: =$J$9 -> 25 | G29: =$J$10 -> 16 | H29: =$J$11+$J$8 -> 5 | I29: =0.5*((F29+G29)*H29) -> 102.5 | J29: =I29*D29 -> 2562.5 | P29: =O30-O28 -> 25 | Q29: =$S$8 -> 0.1 | R29: =$S$9 -> 10 | S29: =Q29*R29 -> 1 | T29: =S29*P29 -> 25
C30: =+C28+25 -> 175 | O30: =+O28+25 -> 175
D31: =C32-C30 -> 25 | E31: =$J$8 -> 2.5 | F31: =$J$9 -> 25 | G31: =$J$10 -> 16 | H31: =$J$11+$J$8 -> 5 | I31: =0.5*((F31+G31)*H31) -> 102.5 | J31: =I31*D31 -> 2562.5 | P31: =O32-O30 -> 25 | Q31: =$S$8 -> 0.1 | R31: =$S$9 -> 10 | S31: =Q31*R31 -> 1 | T31: =S31*P31 -> 25
C32: =+C30+25 -> 200 | O32: =+O30+25 -> 200
D33: =C34-C32 -> 25 | E33: =$J$8 -> 2.5 | F33: =$J$9 -> 25 | G33: =$J$10 -> 16 | H33: =$J$11+$J$8 -> 5 | I33: =0.5*((F33+G33)*H33) -> 102.5 | J33: =I33*D33 -> 2562.5 | P33: =O34-O32 -> 25 | Q33: =$S$8 -> 0.1 | R33: =$S$9 -> 10 | S33: =Q33*R33 -> 1 | T33: =S33*P33 -> 25
C34: =+C32+25 -> 225 | O34: =+O32+25 -> 225
D35: =C36-C34 -> 25 | E35: =$J$8 -> 2.5 | F35: =$J$9 -> 25 | G35: =$J$10 -> 16 | H35: =$J$11+$J$8 -> 5 | I35: =0.5*((F35+G35)*H35) -> 102.5 | J35: =I35*D35 -> 2562.5 | P35: =O36-O34 -> 25 | Q35: =$S$8 -> 0.1 | R35: =$S$9 -> 10 | S35: =Q35*R35 -> 1 | T35: =S35*P35 -> 25
C36: =+C34+25 -> 250 | O36: =+O34+25 -> 250
D37: =C38-C36 -> 25 | E37: =$J$8 -> 2.5 | F37: =$J$9 -> 25 | G37: =$J$10 -> 16 | H37: =$J$11+$J$8 -> 5 | I37: =0.5*((F37+G37)*H37) -> 102.5 | J37: =I37*D37 -> 2562.5 | P37: =O38-O36 -> 25 | Q37: =$S$8 -> 0.1 | R37: =$S$9 -> 10 | S37: =Q37*R37 -> 1 | T37: =S37*P37 -> 25
C38: =+C36+25 -> 275 | O38: =+O36+25 -> 275
D39: =C40-C38 -> 25 | E39: =$J$8 -> 2.5 | F39: =$J$9 -> 25 | G39: =$J$10 -> 16 | H39: =$J$11+$J$8 -> 5 | I39: =0.5*((F39+G39)*H39) -> 102.5 | J39: =I39*D39 -> 2562.5 | P39: =O40-O38 -> 25 | Q39: =$S$8 -> 0.1 | R39: =$S$9 -> 10 | S39: =Q39*R39 -> 1 | T39: =S39*P39 -> 25
C40: =+C38+25 -> 300 | O40: =+O38+25 -> 300
D41: =C42-C40 -> 25 | E41: =$J$8 -> 2.5 | F41: =$J$9 -> 25 | G41: =$J$10 -> 16 | H41: =$J$11+$J$8 -> 5 | I41: =0.5*((F41+G41)*H41) -> 102.5 | J41: =I41*D41 -> 2562.5 | P41: =O42-O40 -> 25 | Q41: =$S$8 -> 0.1 | R41: =$S$9 -> 10 | S41: =Q41*R41 -> 1 | T41: =S41*P41 -> 25
C42: =+C40+25 -> 325 | O42: =+O40+25 -> 325
D43: =C44-C42 -> 25 | E43: =$J$8 -> 2.5 | F43: =$J$9 -> 25 | G43: =$J$10 -> 16 | H43: =$J$11+$J$8 -> 5 | I43: =0.5*((F43+G43)*H43) -> 102.5 | J43: =I43*D43 -> 2562.5 | P43: =O44-O42 -> 25 | Q43: =$S$8 -> 0.1 | R43: =$S$9 -> 10 | S43: =Q43*R43 -> 1 | T43: =S43*P43 -> 25
C44: =+C42+25 -> 350 | O44: =+O42+25 -> 350
D45: =C46-C44 -> 25 | E45: =$J$8 -> 2.5 | F45: =$J$9 -> 25 | G45: =$J$10 -> 16 | H45: =$J$11+$J$8 -> 5 | I45: =0.5*((F45+G45)*H45) -> 102.5 | J45: =I45*D45 -> 2562.5 | P45: =O46-O44 -> 25 | Q45: =$S$8 -> 0.1 | R45: =$S$9 -> 10 | S45: =Q45*R45 -> 1 | T45: =S45*P45 -> 25
C46: =+C44+25 -> 375 | O46: =+O44+25 -> 375
...

Sheet Bahan Upah
C5: DAFTAR HARGA SATUAN DASAR BAHAN DAN ALAT
C6: No. | D6: URAIAN | F6: SAT | G6: HARGA | I6: KETERANGAN | J6: TKDN | K6: Sertifikat | L6: Link
G7: SATUAN ( Rp ) | J7: (%) | L7: TKDN
C8: 1 | D8: 2 | F8: 3 | G8: 4 | I8: 5 | J8: 6 | K8: 7 | L8: 8 | O8: HARGA BINAMARGA 2025 | P8: HARGA LEBAKSARI 2024
D9: Air | F9: Ltr | G9: =ROUND(O9,2) -> 100 | J9: 1 | K9: - | L9: Air Lokal | O9: 100
D10: Batu Pecah 2 - 3 cm | F10: m3 | G10: =ROUND(O10,2) -> 317654.76 | H10: =G10/1350 -> 235.29982 | I10: Include Galian C | J10: 1 | K10: - | L10: Lokal | O10: 317654.76
D11: Besi Polos | F11: kg | G11: =ROUND(O11,2) -> 9209 | J11: 0.5147 | K11: 2951/SJ-IND.8/TKDN/7/2022 | L11: https://tkdn.kemenperin.go.id/sertifikat.php?id=pdvHhTXytRgoPIa-2oCGftCKZXxdzdscW4BMG8o7YW8 | O11: 9209
D12: Besi Ulir | F12: kg | G12: =ROUND(O12,2) -> 8591.81 | J12: 0.5147 | K12: 2951/SJ-IND.8/TKDN/7/2022 | L12: https://tkdn.kemenperin.go.id/sertifikat.php?id=pdvHhTXytRgoPIa-2oCGftCKZXxdzdscW4BMG8o7YW8 | O12: 8591.81
D13: Banner plastik ukuran 1,2 x 0,8 m2 | F13: m2 | G13: =ROUND(P13,2) -> 20000 | J13: 0.7005 | K13: 2031/SJ-IND.8/TKDN/3/2023 | L13: https://tkdn.kemenperin.go.id/sertifikat.php?id=aHl2_F7GrXYbJB6QMwOcknNkmAo9Kk5d5VW1Mgj9_4U, | P13: 20000
D14: Bronjong Kawat Galvanis (Pabrikasi 2 X 1 X 0.5 m lubang 8 x 10 cm kawat 2.7 mmx3,4 mm) | F14: Buah | G14: =ROUND(P14,2) -> 245000 | J14: 0.4351 | K14: 6704/SJ-IND.8/TKDN/11/2022 | L14: https://tkdn.kemenperin.go.id/sertifikat.php?id=mLJ1kGSrlkO-SW2J_MKOIrS6ojiEHk07GrwEwm9MGIk, | P14: 245000
D15: Batu Kali belah hitam (Batu Andesit) | F15: m3 | G15: =ROUND(O15,2) -> 353750 | I15: Include Galian C | J15: 1 | K15: - | L15: Lokal Pamotan | O15: 353750
D16: Beton Ready Mix B0 | F16: m3 | G16: =ROUND(O16,2) -> 0 | J16: 0.9633 | K16: 648/SJ-IND.8/TKDN/1/2023 | L16: https://tkdn.kemenperin.go.id/sertifikat.php?id=RR3TDR_dS_oHhi_Uca2wavMHgS_RRHSVO5IEtLSlWCQ, | O16: 0
D17: Beton Ready Mix Fc' 10 Mpa | F17: m3 | G17: =ROUND(O17,2) -> 858500 | J17: 0.9633 | K17: 648/SJ-IND.8/TKDN/1/2023 | L17: https://tkdn.kemenperin.go.id/sertifikat.php?id=RR3TDR_dS_oHhi_Uca2wavMHgS_RRHSVO5IEtLSlWCQ, | O17: 858500
D18: Beton Ready Mix Fc' 15 Mpa | F18: m3 | G18: =ROUND(O18,2) -> 897692.31 | J18: 0.9416 | K18: 648/SJ-IND.8/TKDN/1/2023 | L18: https://tkdn.kemenperin.go.id/sertifikat.php?id=RR3TDR_dS_oHhi_Uca2wavMHgS_RRHSVO5IEtLSlWCQ, | O18: 897692.31
D19: Beton Ready Mix Fc' 17 Mpa | F19: m3 | G19: =ROUND(O19,2) -> 0 | J19: 0.9436 | K19: 648/SJ-IND.8/TKDN/1/2023 | L19: https://tkdn.kemenperin.go.id/sertifikat.php?id=RR3TDR_dS_oHhi_Uca2wavMHgS_RRHSVO5IEtLSlWCQ, | O19: 0
D20: Beton Ready Mix Fc' 20 Mpa | F20: m3 | G20: =ROUND(O20,2) -> 970615.38 | J20: 0.9424 | K20: 648/SJ-IND.8/TKDN/1/2023 | L20: https://tkdn.kemenperin.go.id/sertifikat.php?id=RR3TDR_dS_oHhi_Uca2wavMHgS_RRHSVO5IEtLSlWCQ, | O20: 970615.38
D21: Beton Ready Mix Fc' 25 Mpa | F21: m3 | G21: =ROUND(O21,2) -> 1017416.7 | J21: 0.9412 | K21: 648/SJ-IND.8/TKDN/1/2023 | L21: https://tkdn.kemenperin.go.id/sertifikat.php?id=RR3TDR_dS_oHhi_Uca2wavMHgS_RRHSVO5IEtLSlWCQ, | O21: 1017416.7
D22: Beton Ready Mix Fc' 30 Mpa | F22: m3 | G22: =ROUND(O22,2) -> 1095384.6 | J22: 0.9401 | K22: 648/SJ-IND.8/TKDN/1/2023 | L22: https://tkdn.kemenperin.go.id/sertifikat.php?id=RR3TDR_dS_oHhi_Uca2wavMHgS_RRHSVO5IEtLSlWCQ, | O22: 1095384.6
D23: Beton Ready Mix Fc' 35 Mpa | F23: m3 | G23: =ROUND(O23,2) -> 0 | J23: 0.9374 | K23: 648/SJ-IND.8/TKDN/1/2023 | L23: https://tkdn.kemenperin.go.id/sertifikat.php?id=RR3TDR_dS_oHhi_Uca2wavMHgS_RRHSVO5IEtLSlWCQ, | O23: 0
D24: Box panel 180 x 120 x 60 cm dengan Isi Lengkap | F24: Unit | G24: =ROUND(O24,2) -> 0 | J24: 0.2269 | L24: https://tkdn.kemenperin.go.id/sertifikat_perush.php?id=v36TaTPoCmAn_ImaBYOilzlMdAyBz-6XgDS1iSG1POY,
D25: Box Culvert 200x200x 120 x 20 cm K-300 | F25: Bh | G25: =ROUND(P25,2) -> 10419500 | J25: 0.7203 | P25: 10419500
D26: Bio Filter Septictank kaps. 2m3 | F26: Unit | G26: =ROUND(O26,2) -> 0 | J26: 0.4062 | K26: 4927/SJ-IND.8/TKDN/10/2022 | L26: https://tkdn.kemenperin.go.id/sertifikat.php?id=JsQBIMOwTCxciWAeWPbnMQ9xD6wRFFonnPwbU2BCc5s
D27: Bentonit | F27: kg | G27: =ROUND(O27,2) -> 0 | J27: 0.6674 | L27: https://tkdn.kemenperin.go.id/sertifikat_perush.php?id=_m0WzcNftQiVRuiLCZLDCfYxq8m087SsglPvUgprQ9c,
D28: Aditif Pengeras Beton | F28: L | G28: =ROUND(O28,2) -> 0 | J28: 0.2295 | L28: https://tkdn.kemenperin.go.id/sertifikat_perush.php?id=AJG1czt-f8v91ffw3UboHPweW6zEouDjHRzI_uI5T1M,
D29: Cat Dasar | F29: Kg | G29: =ROUND(O29,2) -> 39421.05 | J29: 0.4363 | K29: 6618/SJ-IND.8/TKDN/7/2021 | L29: https://tkdn.kemenperin.go.id/sertifikat.php?id=v-zTLESpHiO-bgsgXYzAdlvWPvAyO2s38AVUm0Vo9tE, | O29: 39421.05
D30: Cat Tembok Interior | F30: Kg | G30: =ROUND(O30,2) -> 0 | J30: 0.5481 | K30: 8272/SJ-IND.8/TKDN/9/2023 | L30: https://tkdn.kemenperin.go.id/sertifikat.php?id=-ZxxIzk_t1SkoZ9jJJMm5_quTq1cTOCB6HV6AOK9znk, | O30: 0
D31: Cat Tembok Eksterior | F31: Kg | G31: =ROUND(O31,2) -> 90444.44 | J31: 0.5862 | K31: 8272/SJ-IND.8/TKDN/9/2023 | L31: https://tkdn.kemenperin.go.id/sertifikat.php?id=-ZxxIzk_t1SkoZ9jJJMm5_quTq1cTOCB6HV6AOK9znk, | O31: 90444.44
D32: Cat kayu | F32: kg | G32: =ROUND(O32,2) -> 75000 | J32: 0.2538 | K32: 2231/SJ-IND.8/TKDN/6/2022 | L32: https://tkdn.kemenperin.go.id/sertifikat.php?id=JyyXnL7XXoAZotIUPqdg4QbA2dOVv-o6z-VTRCXmTj4, | O32: 75000
D33: Cerucuk Bambu dia. 8-10 cm | F33: Buah | G33: =ROUND(P33,2) -> 20000 | J33: 1 | K33: - | L33: Bambu Lokal | P33: 20000
D34: Check Valve 10 K ; Dia. 2“ (50 mm) + Material Bantu | F34: uniit | G34: =ROUND(O34,2) -> 0 | J34: 0.2675 | K34: 1600/SJ-IND.8/TKDN/12/2020 | L34: https://tkdn.kemenperin.go.id/sertifikat.php?id=mtU7k04AY78ky_kg3DeYeOYahfroAv1ycDvTy0Q7GqI
D35: Check valve dia 2" | F35: buah | G35: =ROUND(O35,2) -> 0 | J35: 0.2675 | K35: 1600/SJ-IND.8/TKDN/12/2020 | L35: https://tkdn.kemenperin.go.id/sertifikat.php?id=mtU7k04AY78ky_kg3DeYeOYahfroAv1ycDvTy0Q7GqI
D36: Cover U-DICTH 60.120 t.12cm mesh 10 K300 | F36: Bh | G36: =ROUND(O36,2) -> 0 | J36: 0.708 | K36: 6183/SJ-IND.8/TKDN/7/2021 | L36: https://tkdn.kemenperin.go.id/sertifikat_perush.php?id=xT-17pqs3DvKP3AbsSTlC0rFMaEJJqBWx7lkIc9eH48,
D37: Dokumen Review | F37: Ls | G37: =ROUND(O37,2) -> 0 | J37: 0.75 | K37: - | L37: Lokal
D38: Elektrode Las (Kawat Las) | F38: Kg | G38: =ROUND(O38,2) -> 0 | J38: 0.9178 | K38: 2225/SJ-IND.8/TKDN/6/2022 | L38: https://tkdn.kemenperin.go.id/sertifikat.php?id=FGVk3MCGK29Y1usTFmfM4opVLl-h3vLdsp7OxOuR3l0,
D39: Exhaust Fan | F39: Unit | G39: =ROUND(O39,2) -> 0 | J39: 0.5907 | K39: 1338/SJ-IND.8/TKDN/4/2022 | L39: https://tkdn.kemenperin.go.id/sertifikat.php?id=EXAGsAdOZDM3cWiid2QtuJjuMkeSh-YuQUSbbK_CSZs
D40: Exhaust Fan kap.1920 cmh type industrial | F40: Unit | G40: =ROUND(O40,2) -> 0 | J40: 0.5624 | K40: 9741/SJ-IND.8/TKDN/9/2021 Tanggal | L40: https://tkdn.kemenperin.go.id/sertifikat.php?id=EXAGsAdOZDM3cWiid2QtuJjuMkeSh-YuQUSbbK_CSZs
D41: Function Test | F41: Ls | G41: =ROUND(O41,2) -> 0 | J41: 0.75 | K41: - | L41: Lokal
D42: Flange spigot dia 63 mm | F42: bh | G42: =ROUND(O42,2) -> 0 | J42: 0.4313 | K42: 8354/SJ-IND.8/TKDN/8/2021 | L42: https://tkdn.kemenperin.go.id/sertifikat.php?id=Wg9oH6g-nVR7L-NZHefb_xq90ZMXYS1XuQEGQaZHhRk,
D43: Gate valve Ø0,75" | F43: Unit | G43: =ROUND(O43,2) -> 0 | J43: 0.6059 | K43: 6792/SJ-IND.8/TKDN/8/2021 | L43: https://tkdn.kemenperin.go.id/sertifikat.php?id=mXObu1dIjjQ0HU2etyrVwMzBWYGkGK_TLO4dJn6J1zo,
D44: Gate Valve Dia. 3/4“ | F44: Unit | G44: =ROUND(O44,2) -> 0 | J44: 0.6059 | K44: 6792/SJ-IND.8/TKDN/8/2021 | L44: https://tkdn.kemenperin.go.id/sertifikat.php?id=mXObu1dIjjQ0HU2etyrVwMzBWYGkGK_TLO4dJn6J1zo,
...

Sheet backup volume rencana
B1: BACK UP VOLUME RENCANA PEKERJAAN
B3: KEGIATAN | C3: : | D3: NORMALISASI / RESTORASI SUNGAI
B4: PEKERJAAN | C4: : | D4: NORMALISASI AVFOER DESA KARANGDAYU KEC. BAURENO
B5: LOKASI | C5: : | D5: DESA KARANGDAYU KEC. BAURENO
B7: GAMBAR PELAKSANAAN | O7: Galian
E8: RINCIAN PERHITUNGAN VOLUME | O8: Alat Berat
O9: (m3)
E11: Perhitungan Galian
E12: Luas Galian/Timbunan :
E13: lebar atas | F13: b3 | G13: = | H13: =H15 * ( ( H17 + 2*H14 ) / ( H14 + H17 ) ) -> 6.8571429 | K13: Jarak
E14: tinggi eksisting | F14: h' | G14: = | H14: 2.5 | I14: m
E15: Lebar | F15: b1 | G15: = | H15: 4 | I15: m | K15: P1 | L15: P0 | M15: = | N15: 540 | O15: =J24+J25 -> 2013.4286
E16: lebar | F16: b2 | G16: = | H16: =H15 * ( H14 / ( H14 + H17 ) ) -> 2.8571429 | I16: =I15 -> m
E17: tinggi galian | F17: h | G17: = | H17: 1 | I17: m
E18: Luas Stripping
E19: lebar | F19: 3 | G19: m | H19: kedalaman | I19: 0.1 | J19: m
E20: vol stripp | F20: =N15*F19*I19 -> 162 | G20: m
E22: Volume Galian
E24: Volume | F24: Galian | I24: = | J24: =((0.5*(H15+H16))*H17)*N15 -> 1851.4286 | K24: m3
E25: Volume | F25: Stripping | I25: = | J25: =N15*F19*I19 -> 162 | K25: m3
H31: TOTAL | I31: = | J31: =J24+J25 -> 2013.4286 | L31: m3
E32: SUB TOTAL | O32: =O15 -> 2013.4286 | R32: =O37/'Kebutuhan realisasi'!G18 -> 0.98920172 | S32: 0.98920172
D34: Diperiksa
O37: ='Kebutuhan realisasi'!G18*'backup volume rencana'!S32 -> 1993.6686

Sheet ANALISA perencanaan
B1: ANALISA HARGA SATUAN
B2: GALIAN TANAH DENGAN EXCAVATOR
Z3: SE-DBJK-NO.68-2024 | AC3: HAL 94-101
B5: No. | C5: URAIAN | J5: Kode | K5: Koef | L5: Satuan | M5: Ket
B7: I | C7: ASUMSI | D7: ` | AN7: hal 97
B8: 1 | C8: Jam Kerja efektif per hari | J8: Tk | K8: 8 | L8: Jam
B9: 2 | C9: Faktor Pengembangan Material jenuh air | J9: Fk | K9: 0.8 | L9: - | Q9: KiloWatt | R9: Bucket | W9: Horse Power
B10: II | C10: URUTAN KERJA | P10: A | Q10: =0.7457*W10 -> 110.3636 | R10: 0.46 | S10: ( Caterpillar 320D Long Arm ) | W10: 148
C11: a. Excavator (longarm) pada sungai,menggali,urug talud menggunakan tanah bekas galian dan perataan oleh alat berat | X11: =W10*0.92 -> 136.16
C12: b.setiap 5m, excavator pindah lokasi maju ke depan, maka 30 menit pindah tempat berakibat hilang waktu kurang lebih 10 menit (tanah biasa basah) dan 30 menit (rawa) | P12: B | Q12: =0.7457*W12 -> 42.5049 | R12: 0.31 | S12: ( Caterpillar 307E Mini Hydraulic ) | W12: 57 | X12: =W11*0.94 -> 0
P13: C | Q13: =0.7457*W13 -> 70.0958 | R13: 0.65 | S13: ( Caterpillar 313D Series 2 ) | W13: 94 | X13: =W12*0.99 -> 56.43
B14: III | C14: URAIAN PERALATAN | P14: D | Q14: =0.7457*W14 -> 110.3636 | R14: 0.9 | S14: ( Caterpillar 320D Standart ) | W14: 148 | X14: =W13*0.96 -> 90.24
C15: Excavator Long Arm (Lebar <= 12 m urug/gali dekat) | J15: E.15.i | X15: =W14*0.92 -> 136.16
B16: 1 | C16: Tenaga | J16: Pw | K16: 148 | L16: Hp | P16: E | Q16: =0.7457*W16 -> 108.1265 | R16: 0.9 | S16: ( Komatsu Pc 200 Standart ) | W16: 145
B17: 2 | C17: Kapasitas Bucket | J17: V (Cp) | K17: 0.9 | L17: m3 | Q17: =0.7457*W17 -> 0 | X17: =W16*0.92 -> 133.4
B18: 3 | C18: Jam Operasi dalam 1 Tahun (Perkiraan) | J18: w | K18: 2000 | L18: jam | P18: F | Q18: =0.7457*W18 -> 31.3194 | R18: 0.15 | S18: ( Komatsu Pc 45 MR ) | W18: 42
B19: 4 | C19: Faktor Bucket (tabel 9) | J19: Fb | K19: 1 | L19: - | X19: =W18*0.94 -> 39.48
B20: 5 | C20: Faktor Efisiensi Alat (Tabel 4) | J20: Fa | K20: 0.7 | L20: - | P20: D | Q20: =0.7457*W20 -> 110.3636 | R20: 0.9 | S20: ( Caterpillar 320D Standart ) | W20: 148
B21: 6 | C21: Faktor Konversi Galian (Tabel 11); Normal | J21: Fv | K21: 0.8 | L21: - | M21: Normal , >75% | P21: E | Q21: =0.7457*W21 -> 106.6351 | R21: 0.8 | S21: ( Komatsu Pc 200 Standart ) | W21: 143
Q22: =0.7457*W22 -> 31.09569 | R22: 0.22 | S22: cattepillar 305.5 | W22: 41.7
C23: Waktu Siklus(tanah biasa) | J23: Ts1 | L23: menit
B24: 7 | C24: -Menggali saluran lebar lebih dari 10m, swing dan urug talud dekat | J24: T. 1 | K24: 0.65936552 | L24: menit
J25: Ts.1 | K25: =K24 -> 0.65936552 | L25: menit
B26: 8 | C26: Kap.Produksi/Jam = (V x Fb x Fa x 60)/ (Ts.1 x Fv x Fk) | J26: Q1 | K26: =(K17*K19*K20*60)/(K25*K21*K9) -> 89.574748 | L26: m3/jam
B27: 9 | C27: Kap.Produksi/Hari | J27: Q.2 | K27: =K26*K8 -> 716.59798 | L27: m3/hari
B28: 10 | C28: Koefisien Alat/m3=1/Q1 | K28: =1/K26 -> 0.011163861 | L28: jam
C29: Koefisien Penjaga Malam | Q29: Tabel 6.2
B30: 11 | C30: -Penjaga Malam Alat Berat | K30: =(K42/K27)/K42 -> 0.0013954826 | L30: Orang/hari
B32: IV | C32: Biaya Operasi Per Jam Kerja | N32: 2483
C33: Konsumsi Bahan Bakar Fd x Fe x kW xLoad Factor | J33: H | K33: =K39*K38*K37*K36 -> 22.901851 | L33: Liter/jam
C34: Kebutuhan Liter/Hari | J34: h2 | K34: =K33*K8 -> 183.21481 | L34: Liter/Hr
C35: Koef Bahan Bakar perjam(H/Q.1) | K35: =K33/K26 -> 0.25567307
C36: Tenaga Alat berat konversi (kW) | J36: kW | K36: =K16*0.7457 -> 110.3636 | O36: vol real
C37: Load Factor | J37: L/kWh | K37: 0.28 | O37: ='Kebutuhan realisasi'!G18 -> 2015.4318
C38: Faktor efisiensi waktu | E38: 45 | F38: menit | J38: Fe | K38: =E38/60 -> 0.75 | O38: vol rencana
C39: Faktor Daya | E39: 38 | F39: detik | G39: dari | H39: =K24*60 -> 39.561931 | I39: detik | J39: Fd | K39: =(E39/H39) + ((H39-E39)/H39) * 0.7 -> 0.9881558 | O39: ='backup volume rencana'!O32 -> 2013.4286
B41: V | C41: Estimasi Pekerjaan | Q41: Kapasitas Bucket (Fb)
C42: Volume Rencana Pekerjaan | J42: Vol | K42: ='Backup Galian'!F104+'Backup Galian'!Q104 -> 366698.14 | L42: m3
C43: Estimasi Waktu Pekerjaan (Q2 x Volume Rencana) | J43: T.pek | K43: =ROUNDUP(K42/K27,0) -> 512 | L43: Hari
C44: Total Rencana Kebutuhan Solar | J44: Ks | K44: =K42*K35 -> 93754.839 | L44: Liter
...

Sheet PERSONIL
B1: PERHITUNGAN RENCANA TENAGA DAN BAHAN
B3: SUB KEGIATAN | D3: : | E3: ='backup volume rencana'!D3 -> NORMALISASI / RESTORASI SUNGAI
B4: PEKERJAAN | D4: : | E4: ='backup volume rencana'!D4 -> NORMALISASI AVFOER DESA KARANGDAYU KEC. BAURENO
B5: VOLUME | D5: : | E5: ='backup volume rencana'!O32 -> 2013.4286 | F5: m3
B6: LOKASI | D6: : | E6: ='backup volume rencana'!D5 -> DESA KARANGDAYU KEC. BAURENO
B7: DURASI PEKERJAAN | D7: : | E7: =L13 -> 3 | F7: Hari
B9: No. | C9: Uraian | G9: Volume | I9: Koofisien | J9: Vol x Koofisien | L9: Pembulatan | N9: Keterangan
B10: a | C10: b | G10: c | I10: d | J10: ( c / d ) | L10: e | N10: f
B12: A | C12: TENAGA KERJA
B13: 1 | C13: Penjaga Malam 1 | G13: =E5 -> 2013.4286 | H13: m3 | J13: =G13/I17 -> 2.8097045 | K13: hari | L13: =ROUND(J13,0) -> 3 | M13: =K13 -> hari | O13: =L13/30 -> 0.1
B14: 2 | C14: Penjaga Malam 2 | G14: =G13 -> 2013.4286 | H14: m3 | J14: =G13/I17 -> 2.8097045 | K14: hari | L14: =ROUND(J14,0) -> 3 | M14: =K14 -> hari
B16: B | C16: BAHAN
C17: Excavator | G17: 1 | H17: buah | I17: ='ANALISA perencanaan'!K27*PERSONIL!G17 -> 716.59798 | O17: =G18-'RAB PEKERJAAN'!K13 -> 0
B18: 1 | C18: Solar | G18: =E5 -> 2013.4286 | H18: m3 | J18: =('ANALISA perencanaan'!K34/PERSONIL!I17)*G17*G18 -> 514.77946 | K18: ltr | L18: =ROUNDUP(J18,3) -> 514.78 | M18: =K18 -> ltr
C20: Total Biaya (Tanpa PPn)
C21: DIBULATKAN
B24: Mengetahui : | M24: Menyetujui :
M26: PEJABAT PELAKSANA TEKNIS KEGIATAN
M27: DINAS PEKERJAAN UMUM SDA KAB. BOJONEGORO
M32: GALUH SETIAWAN ROSMI, ST
M33: NIP. 19780410 200901 1 011

Sheet RAB PERSONIL
B2: RENCANA ANGGARAN BIAYA PER BAHAN
B4: KEGIATAN | D4: : | E4: =PERSONIL!E3 -> NORMALISASI / RESTORASI SUNGAI
B5: ESTIMASI WAKTU | D5: : | E5: =PERSONIL!E7 -> 3 | F5: Hari
B6: PEKERJAAN | D6: : | E6: =PERSONIL!E4 -> NORMALISASI AVFOER DESA KARANGDAYU KEC. BAURENO
B7: LOKASI | D7: : | E7: =PERSONIL!E6 -> DESA KARANGDAYU KEC. BAURENO
B9: No. | C9: Uraian Pekerjaan | H9: Sat | I9: Volume | J9: Harga Satuan (Rp.) | K9: Harga Setelah PPN | L9: Jumlah Harga (Rp.)
B10: a | C10: b | H10: c | I10: d | J10: e | K10: f = (e x 12% ) x e | L10: g = d x f
B11: A | C11: TENAGA
B12: 1 | C12: Penjaga Malam 1 | H12: Hari | I12: =PERSONIL!L13 -> 3 | J12: ='ANALISA perencanaan'!$AD$73 -> 75000 | L12: =I12*J12 -> 225000 | N12: PAGU | O12: 3600000000
B13: 2 | C13: Penjaga Malam 2 | H13: Hari | I13: =PERSONIL!L14 -> 3 | J13: ='ANALISA perencanaan'!$AD$73 -> 75000 | L13: =I13*J13 -> 225000 | O13: =L19 -> 13307000
B15: B | C15: BAHAN
B16: 1 | C16: Solar | H16: Liter | I16: =PERSONIL!J18 -> 514.77946 | J16: ='ANALISA perencanaan'!$AD$72 -> 22300 | K16: =(J16*12%)+J16 -> 24976 | L16: =I16*K16 -> 12857132
C18: SUB TOTAL A | L18: =SUM(L12:L17) -> 13307132 | O18: =L18-'RAB PEKERJAAN'!N15 -> 0
C19: TOTAL PEMBULATAN | L19: =ROUNDDOWN(L18,-3) -> 13307000
B22: Mengetahui : | J22: Menyetujui :
E24: KUASA PENGGUNA ANGGARAN | J24: PEJABAT PELAKSANA TEKNIS KEGIATAN
E25: SUB KEGIATAN NORMALISASI/RESTORASI SUNGAI | J25: DINAS PEKERJAAN UMUM SDA KAB. BOJONEGORO
E30: =PERSONIL!#REF! -> #REF! | J30: =[63]RINCIAN!M33 -> GALUH SETIAWAN ROSMI, ST
E31: =PERSONIL!#REF! -> #REF! | J31: NIP. 19790511 200312 1 006

Sheet RAB PEKERJAAN
B2: RENCANA ANGGARAN BIAYA
B4: KEGIATAN | D4: : | E4: =PERSONIL!E3 -> NORMALISASI / RESTORASI SUNGAI
B5: ESTIMASI WAKTU | D5: : | E5: =PERSONIL!E7 -> 3 | F5: Hari
B6: PEKERJAAN | D6: : | E6: =PERSONIL!E4 -> NORMALISASI AVFOER DESA KARANGDAYU KEC. BAURENO
B7: LOKASI | D7: : | E7: =PERSONIL!E6 -> DESA KARANGDAYU KEC. BAURENO
B9: No. | C9: Uraian Pekerjaan | J9: Sat | K9: Volume | L9: Harga Satuan (Rp.) | M9: Harga Setelah PPN | N9: Jumlah Harga (Rp.)
B10: a | C10: b | J10: c | K10: d | L10: e | M10: f | N10: g = e x f
B12: A | C12: PEKERJAAN TANAH | Q12: 3600000000
B13: 1 | C13: menggali dan menimbun menggunakan Excavator | J13: m3 | K13: ='backup volume rencana'!O32 -> 2013.4286 | L13: ='ANALISA perencanaan'!$AB$101 -> 5701.5094 | M13: =(L13*12%)+L13 -> 6385.6906 | N13: =K13*M13 -> 12857132 | O13: =N13-'RAB PERSONIL'!L16 -> 0 | P13: PAGU | Q13: 3000000000
B14: 2 | C14: Jasa Keamanan | J14: OH | K14: =PERSONIL!B14*'RAB PERSONIL'!I12 -> 6 | L14: ='ANALISA perencanaan'!$AD$73 -> 75000 | N14: =K14*L14 -> 450000 | Q14: =Q12-N17 -> 3586693000
C15: TOTAL PEKERJAAN TANAH | N15: =SUM(N12:N14) -> 13307132 | Q15: =N15-'RAB PERSONIL'!L18 -> 0
C16: SUB TOTAL A + B | N16: =N15 -> 13307132
C17: TOTAL PEMBULATAN | N17: =ROUNDDOWN(N16,-3) -> 13307000
N18: =N17-'RAB PERSONIL'!L19 -> 0
E20: Menyetujui : | L20: Mengetahui :
E22: KUASA PENGGUNA ANGGARAN | L22: PEJABAT PELAKSANA TEKNIS KEGIATAN
E23: SUB KEGIATAN NORMALISASI/RESTORASI SUNGAI | L23: SUB KEGIATAN NORMALISASI/RESTORASI SUNGAI
E28: JAFAR SODIQ, ST, MM | L28: =[63]RINCIAN!M33 -> GALUH SETIAWAN ROSMI, ST
E29: NIP.19760818 200312 1 005 | L29: NIP. 19790511 200312 1 006

Sheet ANALISA pelaksanaan 
B1: ANALISA HARGA SATUAN
B2: GALIAN TANAH DENGAN EXCAVATOR
Z3: SE-DBJK-NO.68-2024 | AC3: HAL 94-101
B5: No. | C5: URAIAN | J5: Kode | K5: Koef | L5: Satuan | M5: Ket
B7: I | C7: ASUMSI | D7: ` | AN7: hal 97
B8: 1 | C8: Jam Kerja efektif per hari | J8: Tk | K8: 8 | L8: Jam
B9: 2 | C9: Faktor Pengembangan Material jenuh air | J9: Fk | K9: 0.8 | L9: - | Q9: KiloWatt | R9: Bucket | W9: Horse Power
B10: II | C10: URUTAN KERJA | P10: A | Q10: =0.7457*W10 -> 110.3636 | R10: 0.46 | S10: ( Caterpillar 320D Long Arm ) | W10: 148
C11: a. Excavator (longarm) pada sungai,menggali,urug talud menggunakan tanah bekas galian dan perataan oleh alat berat | X11: =W10*0.92 -> 136.16
C12: b.setiap 5m, excavator pindah lokasi maju ke depan, maka 30 menit pindah tempat berakibat hilang waktu kurang lebih 10 menit (tanah biasa basah) dan 30 menit (rawa) | P12: B | Q12: =0.7457*W12 -> 42.5049 | R12: 0.31 | S12: ( Caterpillar 307E Mini Hydraulic ) | W12: 57 | X12: =W11*0.94 -> 0
P13: C | Q13: =0.7457*W13 -> 70.0958 | R13: 0.65 | S13: ( Caterpillar 313D Series 2 ) | W13: 94 | X13: =W12*0.99 -> 56.43
B14: III | C14: URAIAN PERALATAN | P14: D | Q14: =0.7457*W14 -> 110.3636 | R14: 0.9 | S14: ( Caterpillar 320D Standart ) | W14: 148 | X14: =W13*0.96 -> 90.24
C15: Excavator Long Arm (Lebar <= 12 m urug/gali dekat) | J15: E.15.i | X15: =W14*0.92 -> 136.16
B16: 1 | C16: Tenaga | J16: Pw | K16: ='ANALISA perencanaan'!K16 -> 148 | L16: Hp | P16: E | Q16: =0.7457*W16 -> 108.1265 | R16: 0.9 | S16: ( Komatsu Pc 200 Standart ) | W16: 145
B17: 2 | C17: Kapasitas Bucket | J17: V (Cp) | K17: ='ANALISA perencanaan'!K17 -> 0.9 | L17: m3 | Q17: =0.7457*W17 -> 0 | X17: =W16*0.92 -> 133.4
B18: 3 | C18: Jam Operasi dalam 1 Tahun (Perkiraan) | J18: w | K18: ='ANALISA perencanaan'!K18 -> 2000 | L18: jam | P18: F | Q18: =0.7457*W18 -> 31.3194 | R18: 0.15 | S18: ( Komatsu Pc 45 MR ) | W18: 42
B19: 4 | C19: Faktor Bucket (tabel 9) | J19: Fb | K19: ='ANALISA perencanaan'!K19 -> 1 | L19: - | X19: =W18*0.94 -> 39.48
B20: 5 | C20: Faktor Efisiensi Alat (Tabel 4) | J20: Fa | K20: ='ANALISA perencanaan'!K20 -> 0.7 | L20: - | P20: D | Q20: =0.7457*W20 -> 110.3636 | R20: 0.9 | S20: ( Caterpillar 320D Standart ) | W20: 148
B21: 6 | C21: Faktor Konversi Galian (Tabel 11); Normal | J21: Fv | K21: ='ANALISA perencanaan'!K21 -> 0.8 | L21: - | M21: Normal , >75% | P21: E | Q21: =0.7457*W21 -> 106.6351 | R21: 0.8 | S21: ( Komatsu Pc 200 Standart ) | W21: 143
Q22: =0.7457*W22 -> 31.09569 | R22: 0.22 | S22: cattepillar 305.5 | W22: 41.7
C23: Waktu Siklus(tanah biasa) | J23: Ts1 | L23: menit
B24: 7 | C24: -Menggali saluran lebar lebih dari 10m, swing dan urug talud dekat | J24: T. 1 | K24: ='ANALISA perencanaan'!K24 -> 0.65936552 | L24: menit
J25: Ts.1 | K25: =K24 -> 0.65936552 | L25: menit
B26: 8 | C26: Kap.Produksi/Jam = (V x Fb x Fa x 60)/ (Ts.1 x Fv x Fk) | J26: Q1 | K26: =(K17*K19*K20*60)/(K25*K21*K9) -> 89.574748 | L26: m3/jam
B27: 9 | C27: Kap.Produksi/Hari | J27: Q.2 | K27: =K26*K8 -> 716.59798 | L27: m3/hari
B28: 10 | C28: Koefisien Alat/m3=1/Q1 | K28: =1/K26 -> 0.011163861 | L28: jam
C29: Koefisien Penjaga Malam | Q29: Tabel 6.2
B30: 11 | C30: -Penjaga Malam Alat Berat | K30: =(K42/K27)/K42 -> 0.0013954826 | L30: Orang/hari
B32: IV | C32: Biaya Operasi Per Jam Kerja
C33: Konsumsi Bahan Bakar Fd x Fe x kW xLoad Factor | J33: H | K33: =K39*K38*K37*K36 -> 22.901851 | L33: Liter/jam
C34: Kebutuhan Liter/Hari | J34: h2 | K34: =K33*K8 -> 183.21481 | L34: Liter/Hr
C35: Koef Bahan Bakar perjam(H/Q.1) | K35: =K33/K26 -> 0.25567307
C36: Tenaga Alat berat konversi (kW) | J36: kW | K36: =K16*0.7457 -> 110.3636
C37: Load Factor | J37: L/kWh | K37: ='ANALISA perencanaan'!K37 -> 0.28
C38: Faktor efisiensi waktu | E38: ='ANALISA perencanaan'!E38 -> 45 | F38: menit | J38: Fe | K38: =E38/60 -> 0.75
C39: Faktor Daya | E39: 38 | F39: detik | G39: dari | H39: =K24*60 -> 39.561931 | I39: detik | J39: Fd | K39: =(E39/H39) + ((H39-E39)/H39) * 0.7 -> 0.9881558
N40: 9.5505302
B41: V | C41: Estimasi Pekerjaan | Q41: Kapasitas Bucket (Fb)
C42: Volume Rencana Pekerjaan | J42: Vol | K42: ='Backup Galian'!F104+'Backup Galian'!Q104 -> 366698.14 | L42: m3
C43: Estimasi Waktu Pekerjaan (Q2 x Volume Rencana) | J43: T.pek | K43: =ROUNDUP(K42/K27,0) -> 512 | L43: Hari
...

Sheet Kebutuhan  realisasi
A1: RINCIAN KEBUTUHAN DAN HASIL PELAKSANAAN
A2: - | B2: =[64]RINCIAN!A3 -> SUB KEGIATAN | D2: =PERSONIL!E3 -> NORMALISASI / RESTORASI SUNGAI
A3: - | B3: =[64]RINCIAN!A4 -> PEKERJAAN | D3: =PERSONIL!E4 -> NORMALISASI AVFOER DESA KARANGDAYU KEC. BAURENO
A4: - | B4: =[64]RINCIAN!A6 -> LOKASI | D4: =PERSONIL!E6 -> DESA KARANGDAYU KEC. BAURENO
A6: No | B6: TANGGAL | E6: JAM | F6: HASIL GALIAN (m3) | H6: KEBUTUHAN BAHAN BAKAR (liter)
E7: KERJA | F7: Perjam | G7: dlm 1 hari | H7: Perjam | I7: dlm 1 hari | J7: Diterima | K7: Sisa
A9: 1 | B9: 16 | C9: Januari | D9: 2025 | E9: 3.8 | F9: ='ANALISA pelaksanaan '!K26 -> 89.574748 | G9: =F9*E9 -> 340.38404 | H9: ='ANALISA pelaksanaan '!K33 -> 22.901851 | I9: =H9*E9 -> 87.027033 | K9: 55
A10: 2 | B10: 17 | C10: Januari | D10: 2025 | E10: 6.3 | F10: ='ANALISA pelaksanaan '!K26 -> 89.574748 | G10: =F10*E10 -> 564.32091 | H10: ='ANALISA pelaksanaan '!K33 -> 22.901851 | I10: =H10*E10 -> 144.28166 | J10: 600 | K10: =(J10+K9)-I10+J9 -> 510.71834 | M10: 0 | N10: 0
A11: 3 | B11: 18 | C11: Januari | D11: =D10 -> 2025 | E11: 0 | F11: =F10 -> 89.574748 | G11: =F11*E11 -> 0 | H11: =H10 -> 22.901851 | I11: =H11*E11 -> 0 | K11: =(J11+K10)-I11 -> 510.71834 | M11: 954.9 | N11: 961.6
A12: 4 | B12: 19 | C12: Januari | D12: =D11 -> 2025 | E12: 0 | F12: =F11 -> 89.574748 | G12: =F12*E12 -> 0 | H12: =H11 -> 22.901851 | I12: =H12*E12 -> 0 | K12: =(J12+K11)-I12 -> 510.71834 | M12: 0 | N12: 0
A13: 5 | B13: 20 | C13: Januari | D13: =D12 -> 2025 | E13: 7.9 | F13: =F12 -> 89.574748 | G13: =F13*E13 -> 707.64051 | H13: =H12 -> 22.901851 | I13: =H13*E13 -> 180.92462 | K13: =(J13+K12)-I13 -> 329.79372 | M13: 0 | N13: 0
A14: 6 | B14: 21 | C14: Januari | D14: =D13 -> 2025 | E14: 0 | F14: =F13 -> 89.574748 | G14: =F14*E14 -> 0 | H14: =H13 -> 22.901851 | I14: =H14*E14 -> 0 | K14: =(J14+K13)-I14 -> 329.79372 | M14: =N11 -> 961.6 | N14: 969.6
A15: 7 | B15: 22 | C15: Januari | D15: =D14 -> 2025 | E15: 0 | F15: =F14 -> 89.574748 | G15: =F15*E15 -> 0 | H15: =H14 -> 22.901851 | I15: =H15*E15 -> 0 | K15: =(J15+K14)-I15 -> 329.79372 | M15: =N14 -> 969.6 | N15: 975.8
A16: 8 | B16: 23 | C16: Januari | D16: =D15 -> 2025 | E16: 0 | F16: =F15 -> 89.574748 | G16: =F16*E16 -> 0 | H16: =H15 -> 22.901851 | I16: =H16*E16 -> 0 | K16: =(J16+K15)-I16 -> 329.79372 | M16: =N15 -> 975.8 | N16: 983.2
A17: 9 | B17: 24 | C17: Januari | D17: =D16 -> 2025 | E17: 8.3 | F17: =F16 -> 89.574748 | G17: =F17*E17 -> 743.47041 | H17: =H16 -> 22.901851 | I17: =H17*E17 -> 190.08536 | K17: =(J17+K16)-I17 -> 139.70836 | M17: =N16 -> 983.2 | N17: 990.7
G18: =SUM(G10:G17) -> 2015.4318 | I18: =SUM(I10:I17) -> 515.29164 | J18: =SUM(J9:J17) -> 600
J19: =J18-#REF! -> #REF!
M20: =#REF!-#REF! -> #REF!
M21: =M20/8 -> #REF!
F23: `

Sheet backup volume Pelaksanaan
B1: BACK UP VOLUME PEKERJAAN
B3: KEGIATAN | C3: : | D3: NORMALISASI / RESTORASI SUNGAI
B4: PEKERJAAN | C4: : | D4: ='Kebutuhan realisasi'!D3 -> NORMALISASI AVFOER DESA KARANGDAYU KEC. BAURENO
B5: LOKASI | C5: : | D5: ='Kebutuhan realisasi'!D4 -> DESA KARANGDAYU KEC. BAURENO
B7: GAMBAR PELAKSANAAN | O7: Galian
E8: RINCIAN PERHITUNGAN VOLUME | O8: Alat Berat
O9: (m3)
K10: JARAK TOTAL | M10: = | N10: ='backup volume rencana'!N15 -> 540
E11: Perhitungan Galian
E12: ="STA = + "&$N$10-($N$10*100%) -> STA = + 0 | F12: Luas Galian/Timbunan :
E13: Lebar Atas | F13: b3 | G13: = | H13: ='backup volume rencana'!H13 -> 6.8571429 | I13: m
E14: tinggi eksisting | F14: h' | G14: = | H14: ='backup volume rencana'!H14 -> 2.5 | I14: m
E15: Lebar | F15: b1 | G15: = | H15: ='backup volume rencana'!H15 -> 4 | I15: m
E16: lebar | F16: b2 | G16: = | H16: =H15 * ( H14 / ( H14 + H17 ) ) -> 2.8571429 | I16: =I15 -> m
E17: tinggi galian | F17: h | G17: = | H17: ='backup volume rencana'!H17 -> 1 | I17: m | P17: REALISASI | Q17: ='Kebutuhan realisasi'!G18 -> 2015.4318
P18: BACKUP | Q18: =O85 -> 2015.4318
E20: ="STA = + "&$N$10-($N$10*75%) -> STA = + 135 | F20: Luas Galian/Timbunan : | Q20: 4102.3404
E21: Lebar Atas | F21: b3 | G21: = | H21: =H23 * ( ( H25 + 2*H22 ) / ( H22 + H25 ) ) -> 6.1718962 | I21: m
E22: tinggi eksisting | F22: h' | G22: = | H22: =H14 -> 2.5 | I22: m
E23: Lebar | F23: b1 | G23: = | H23: 3.6002728 | I23: m | K23: JARAK ANTAR STA | M23: = | N23: =N$10-($N$10*75%) -> 135 | O23: =J32+J33 -> 506.44309
E24: lebar | F24: b2 | G24: = | H24: =H23 * ( H22 / ( H22 + H25 ) ) -> 2.5716234 | I24: =I23 -> m | K24: luasan | L24: =0.5*(H23+H24)*H25 -> 3.0859481
E25: tinggi galian | F25: h | G25: = | H25: =H17 -> 1 | I25: m
E26: Luas Stripping
E27: lebar | F27: ='backup volume rencana'!F19 -> 3 | G27: m | H27: kedalaman | I27: ='backup volume rencana'!I19 -> 0.1 | J27: m
E28: vol stripp | F28: =N23*F27*I27 -> 40.5 | G28: m
E30: Volume Galian
E32: Volume | F32: Galian | I32: = | J32: =(((0.5*(H23+H24))*H25)+((0.5*(H15+H16))*H17)*N23) -> 465.94309 | K32: m3
E33: Volume | F33: Stripping | I33: = | J33: =N23*F27*I27 -> 40.5 | K33: m3
E36: ="STA = + "&$N$10-($N$10*50%) -> STA = + 270 | F36: Luas Galian/Timbunan :
E37: Lebar Atas | F37: b3 | G37: = | H37: =H39 * ( ( H41 + 2*H38 ) / ( H38 + H41 ) ) -> 7.0285714 | I37: m
E38: tinggi eksisting | F38: h' | G38: = | H38: =H22 -> 2.5 | I38: m
E39: Lebar | F39: b1 | G39: = | H39: =H15*1.025 -> 4.1 | I39: m | K39: JARAK ANTAR STA | M39: = | N39: =(N$10-($N$10*50%))-N23 -> 135 | O39: =J48+J49 -> 460.61728
E40: lebar | F40: b2 | G40: = | H40: =H39 * ( H38 / ( H38 + H41 ) ) -> 2.9285714 | I40: =I39 -> m | K40: luasan | L40: =0.5*(H39+H40)*H41 -> 3.5142857
E41: tinggi galian | F41: h | G41: = | H41: =H25 -> 1 | I41: m
E42: Luas Stripping
E43: lebar | F43: =F27 -> 3 | G43: m | H43: kedalaman | I43: =I27 -> 0.1 | J43: m
E44: vol stripp | F44: =N39*F43*I43 -> 40.5 | G44: m
E46: Volume Galian
E48: Volume | F48: Galian | I48: = | J48: =((0.5*(H39+H40))*H41)+((0.5*(H23+H24))*H25)*N39 -> 420.11728 | K48: m3
E49: Volume | F49: Stripping | I49: = | J49: =N39*F43*I43 -> 40.5 | K49: m3
...

Sheet PERSONIL pelaksanaan
B1: PERHITUNGAN TENAGA DAN BAHAN
B3: SUB KEGIATAN | D3: : | E3: ='backup volume rencana'!D3 -> NORMALISASI / RESTORASI SUNGAI
B4: PEKERJAAN | D4: : | E4: ='backup volume rencana'!D4 -> NORMALISASI AVFOER DESA KARANGDAYU KEC. BAURENO
B5: VOLUME | D5: : | E5: ='backup volume Pelaksanaan'!O85 -> 2015.4318 | F5: m3
B6: LOKASI | D6: : | E6: ='backup volume rencana'!D5 -> DESA KARANGDAYU KEC. BAURENO
B7: DURASI PEKERJAAN | D7: : | E7: =COUNTA('Kebutuhan realisasi'!B9:B68)-1 -> 8 | F7: Hari
E8: P[
B9: No. | C9: Uraian | G9: Volume | I9: Koofisien | J9: Vol x Koofisien | L9: Pembulatan | N9: Keterangan
B10: a | C10: b | G10: c | I10: d | J10: ( c / d ) | L10: e | N10: f
B12: A | C12: TENAGA KERJA
B13: 1 | C13: Penjaga Malam 1 | G13: =E5 -> 2015.4318 | H13: m3 | J13: =E7 -> 8 | K13: hari | L13: =ROUND(J13,0) -> 8 | M13: =K13 -> hari | O13: =L13/30 -> 0.26666667
B14: 2 | C14: Penjaga Malam 2 | G14: =G13 -> 2015.4318 | H14: m3 | J14: =E7 -> 8 | K14: hari | L14: =ROUND(J14,0) -> 8 | M14: =K14 -> hari
B16: B | C16: BAHAN
C17: Excavator | G17: 1 | H17: buah | I17: ='ANALISA pelaksanaan '!K27*'PERSONIL pelaksanaan'!G17 -> 716.59798 | O17: =G18-'RAB PEKERJAAN'!K13 -> 2.0032286
B18: 1 | C18: Solar | G18: =E5 -> 2015.4318 | H18: m3 | J18: =('ANALISA pelaksanaan '!K34/'PERSONIL pelaksanaan'!I17)*G17*G18 -> 515.29163 | K18: ltr | L18: =ROUNDUP(J18,3) -> 515.292 | M18: =K18 -> ltr
C20: Total Biaya (Tanpa PPn)
C21: DIBULATKAN
B24: Mengetahui : | M24: Menyetujui :
M26: PEJABAT PELAKSANA TEKNIS KEGIATAN
M27: DINAS PEKERJAAN UMUM SDA KAB. BOJONEGORO
M32: GALUH SETIAWAN ROSMI, ST
M33: NIP. 19780410 200901 1 011

Sheet RAB PERSONIL PELAKSANAAN
B2: REALISASI ANGGARAN PELAKSANAAN PER BAHAN
B4: KEGIATAN | D4: : | E4: =PERSONIL!E3 -> NORMALISASI / RESTORASI SUNGAI
B5: ESTIMASI WAKTU | D5: : | E5: ='PERSONIL pelaksanaan'!E7 -> 8 | F5: Hari
B6: PEKERJAAN | D6: : | E6: =PERSONIL!E4 -> NORMALISASI AVFOER DESA KARANGDAYU KEC. BAURENO
B7: LOKASI | D7: : | E7: =PERSONIL!E6 -> DESA KARANGDAYU KEC. BAURENO
B9: No. | C9: Uraian Pekerjaan | H9: Sat | I9: Volume | J9: Harga Satuan (Rp.) | K9: Harga Setelah PPN | L9: Jumlah Harga (Rp.)
B10: a | C10: b | H10: c | I10: d | J10: e | K10: f = (e x 12% ) x e | L10: g = d x f
B11: A | C11: TENAGA
B12: 1 | C12: Penjaga Malam 1 | H12: Hari | I12: =E5 -> 8 | J12: ='ANALISA perencanaan'!$AD$73 -> 75000 | L12: =I12*J12 -> 600000 | N12: PAGU | O12: 3600000000
B13: 2 | C13: Penjaga Malam 2 | H13: Hari | I13: =E5 -> 8 | J13: ='ANALISA perencanaan'!$AD$73 -> 75000 | L13: =I13*J13 -> 600000 | O13: =L19 -> 14069000
B15: B | C15: BAHAN
B16: 1 | C16: Solar | H16: Liter | I16: ='PERSONIL pelaksanaan'!J18 -> 515.29163 | J16: ='ANALISA perencanaan'!$AD$72 -> 22300 | K16: =(J16*12%)+J16 -> 24976 | L16: =I16*K16 -> 12869924
C18: SUB TOTAL A | L18: =SUM(L12:L17) -> 14069924 | O18: =L18-'RAB PEKERJAAN'!N15 -> 762792
C19: TOTAL PEMBULATAN | L19: =ROUNDDOWN(L18,-3) -> 14069000
B22: Mengetahui : | J22: Menyetujui :
E24: KUASA PENGGUNA ANGGARAN | J24: PEJABAT PELAKSANA TEKNIS KEGIATAN
E25: SUB KEGIATAN NORMALISASI/RESTORASI SUNGAI | J25: DINAS PEKERJAAN UMUM SDA KAB. BOJONEGORO
E30: =PERSONIL!#REF! -> #REF! | J30: =[63]RINCIAN!M33 -> GALUH SETIAWAN ROSMI, ST
E31: =PERSONIL!#REF! -> #REF! | J31: NIP. 19790511 200312 1 006

Sheet RAB PELAKSANAAN
B2: REALISASI ANGGARAN PELAKSANAAN
B4: KEGIATAN | D4: : | E4: =PERSONIL!E3 -> NORMALISASI / RESTORASI SUNGAI
B5: ESTIMASI WAKTU | D5: : | E5: ='RAB PERSONIL PELAKSANAAN'!E5 -> 8 | F5: Hari
B6: PEKERJAAN | D6: : | E6: =PERSONIL!E4 -> NORMALISASI AVFOER DESA KARANGDAYU KEC. BAURENO
B7: LOKASI | D7: : | E7: =PERSONIL!E6 -> DESA KARANGDAYU KEC. BAURENO
B9: No. | C9: Uraian Pekerjaan | J9: Sat | K9: Volume | L9: Harga Satuan (Rp.) | M9: Harga Setelah PPN | N9: Jumlah Harga (Rp.)
B10: a | C10: b | J10: c | K10: d | L10: e | M10: f | N10: g = e x f
B12: A | C12: PEKERJAAN TANAH | Q12: 3600000000
B13: 1 | C13: menggali dan menimbun menggunakan Excavator | J13: m3 | K13: ='PERSONIL pelaksanaan'!E5 -> 2015.4318 | L13: ='ANALISA pelaksanaan '!AB101 -> 5701.5094 | M13: =(L13*12%)+L13 -> 6385.6906 | N13: =K13*M13 -> 12869924 | O13: =N13-'RAB PERSONIL'!L16 -> 12791.998 | P13: PAGU | Q13: 3000000000
B14: 2 | C14: Jasa Keamanan | J14: OH | K14: =SUM('RAB PERSONIL PELAKSANAAN'!I12:I13) -> 16 | L14: ='ANALISA perencanaan'!$AD$73 -> 75000 | N14: =K14*L14 -> 1200000 | Q14: =Q12-N17 -> 3585931000
C15: TOTAL PEKERJAAN TANAH | N15: =SUM(N12:N14) -> 14069924 | Q15: =N15-'RAB PERSONIL'!L18 -> 762792
C16: SUB TOTAL A + B | N16: =N15 -> 14069924
C17: TOTAL PEMBULATAN | N17: =ROUNDDOWN(N16,-3) -> 14069000 | O17: =N17-'RAB PERSONIL'!L19 -> 762000
E20: Menyetujui : | L20: Mengetahui :
E22: KUASA PENGGUNA ANGGARAN | L22: PEJABAT PELAKSANA TEKNIS KEGIATAN
E23: SUB KEGIATAN NORMALISASI/RESTORASI SUNGAI | L23: ='RAB PEKERJAAN'!L23 -> SUB KEGIATAN NORMALISASI/RESTORASI SUNGAI
E28: ='RAB PEKERJAAN'!E28 -> JAFAR SODIQ, ST, MM | L28: =[63]RINCIAN!M33 -> GALUH SETIAWAN ROSMI, ST
E29: ='RAB PEKERJAAN'!E29 -> NIP.19760818 200312 1 005 | L29: NIP. 19790511 200312 1 006

Sheet Sheet1

Sheet Backup Galian
C2: BACK UP GALIAN | N2: BACK UP STRIPING
C4: Pekerjaan : | D4: Galian tanah menggunakan alat berat (secara mekanis) | N4: Pekerjaan : | O4: Striping, penghamparan dan pemadatan badan tanggul tanah
C5: Satuan : | D5: M3 | N5: Satuan : | O5: M3
A7: =137.7-134.19 -> 3.51
A8: =163.915-3.5 -> 160.415
A9: 157.164
A10: 163.915
A11: =A10-A9 -> 6.751
A12: =155+(9.904) -> 164.904 | C12: STA | D12: Jarak | E12: Luasan (m2) | F12: Volume (m3) | L12: =141-134 -> 7 | N12: STA | O12: Jarak | P12: Luasan (m2) | Q12: Volume (m3)
C13: 0 | N13: 0
D14: =C15-C13 -> 25 | F14: =E14*D14 -> 0 | O14: =N15-N13 -> 25 | P14: 10 | Q14: =P14*O14 -> 250
C15: =+C13+25 -> 25 | N15: =+N13+25 -> 25
D16: =C17-C15 -> 25 | F16: =E16*D16 -> 0 | O16: =N17-N15 -> 25 | P16: 10 | Q16: =P16*O16 -> 250
C17: =+C15+25 -> 50 | N17: =+N15+25 -> 50
A18: =E18*D18 -> 55.885 | D18: =C19-C17 -> 25 | E18: 2.2354 | F18: =E18*D18 -> 55.885 | O18: =N19-N17 -> 25 | P18: 10 | Q18: =P18*O18 -> 250
A19: =E19*D19 -> 0 | C19: =+C17+25 -> 75 | N19: =+N17+25 -> 75
A20: =E20*D20 -> 174.8475 | D20: =C21-C19 -> 25 | E20: 6.9939 | F20: =E20*D20 -> 174.8475 | O20: =N21-N19 -> 25 | P20: 15 | Q20: =P20*O20 -> 375
A21: =E21*D21 -> 0 | C21: =+C19+25 -> 100 | N21: =+N19+25 -> 100
A22: =E22*D22 -> 1359.7825 | D22: =C23-C21 -> 25 | E22: 54.3913 | F22: =E22*D22 -> 1359.7825 | O22: =N23-N21 -> 25 | P22: 15 | Q22: =P22*O22 -> 375
A23: =E23*D23 -> 0 | C23: =+C21+25 -> 125 | N23: =+N21+25 -> 125
A24: =E24*D24 -> 2137.8725 | D24: =C25-C23 -> 25 | E24: 85.5149 | F24: =E24*D24 -> 2137.8725 | O24: =N25-N23 -> 25 | P24: 10 | Q24: =P24*O24 -> 250
A25: =E25*D25 -> 0 | C25: =+C23+25 -> 150 | N25: =+N23+25 -> 150
A26: =E26*D26 -> 2878.5775 | D26: =C27-C25 -> 25 | E26: 115.1431 | F26: =E26*D26 -> 2878.5775 | O26: =N27-N25 -> 25 | P26: 10 | Q26: =P26*O26 -> 250
A27: =E27*D27 -> 0 | C27: =+C25+25 -> 175 | N27: =+N25+25 -> 175
A28: =E28*D28 -> 3387.6925 | D28: =C29-C27 -> 25 | E28: 135.5077 | F28: =E28*D28 -> 3387.6925 | O28: =N29-N27 -> 25 | P28: 10 | Q28: =P28*O28 -> 250
A29: =E29*D29 -> 0 | C29: =+C27+25 -> 200 | N29: =+N27+25 -> 200
A30: =E30*D30 -> 4607.08 | D30: =C31-C29 -> 25 | E30: 184.2832 | F30: =E30*D30 -> 4607.08 | O30: =N31-N29 -> 25 | P30: 15 | Q30: =P30*O30 -> 375
A31: =E31*D31 -> 0 | C31: =+C29+25 -> 225 | N31: =+N29+25 -> 225
A32: =E32*D32 -> 4810.825 | D32: =C33-C31 -> 25 | E32: 192.433 | F32: =E32*D32 -> 4810.825 | O32: =N33-N31 -> 25 | P32: 15 | Q32: =P32*O32 -> 375
A33: =E33*D33 -> 0 | C33: =+C31+25 -> 250 | N33: =+N31+25 -> 250
A34: =E34*D34 -> 7106.9 | D34: =C35-C33 -> 25 | E34: 284.276 | F34: =E34*D34 -> 7106.9 | O34: =N35-N33 -> 25 | P34: 10 | Q34: =P34*O34 -> 250
A35: =E35*D35 -> 0 | C35: =+C33+25 -> 275 | N35: =+N33+25 -> 275
A36: =E36*D36 -> 11272.562 | D36: =C37-C35 -> 25 | E36: 450.9025 | F36: =E36*D36 -> 11272.562 | O36: =N37-N35 -> 25 | P36: 0 | Q36: =P36*O36 -> 0
A37: =E37*D37 -> 0 | C37: =+C35+25 -> 300 | N37: =+N35+25 -> 300
A38: =E38*D38 -> 17700.717 | D38: =C39-C37 -> 25 | E38: 708.0287 | F38: =E38*D38 -> 17700.717 | O38: =N39-N37 -> 25 | P38: 0 | Q38: =P38*O38 -> 0
A39: =E39*D39 -> 0 | C39: =+C37+25 -> 325 | N39: =+N37+25 -> 325
A40: =E40*D40 -> 15905.35 | D40: =C41-C39 -> 25 | E40: 636.214 | F40: =E40*D40 -> 15905.35 | O40: =N41-N39 -> 25 | P40: 0 | Q40: =P40*O40 -> 0
A41: =E41*D41 -> 0 | C41: =+C39+25 -> 350 | N41: =+N39+25 -> 350
A42: =E42*D42 -> 18750.228 | D42: =C43-C41 -> 25 | E42: 750.0091 | F42: =E42*D42 -> 18750.228 | O42: =N43-N41 -> 25 | P42: 0 | Q42: =P42*O42 -> 0
A43: =E43*D43 -> 0 | C43: =+C41+25 -> 375 | N43: =+N41+25 -> 375
...

Sheet ELEVASI
B2: DATA ELEVASI
C4: DASAR SUNGAI HULU EXISTING 0+050 | F4: DASAR SUNGAI HILIR EXISTING 1+125
A6: =155+(9.904) -> 164.904 | C6: STA | D6: ELEVASI DATUM | E6: ELEVASI EKSISTING | F6: RENCANA | G6: ELEVASI RENCANA | H6: BEDA ELEVASI
A7: =155+(9.135) -> 164.135
C8: 0 | D8: 155 | E8: 163.915
C9: =+C8+25 -> 25 | D9: 155 | E9: 164.071 | J9: CEK MULAI 525
C10: =+C9+25 -> 50 | D10: 155 | E10: 163.904 | F10: 8.7 | G10: =D10+F10 -> 163.7 | H10: =E10-G10 -> 0.204
C11: =+C10+25 -> 75 | D11: 155 | E11: 164.315 | F11: 8.5442 | G11: =D11+F11 -> 163.5442 | H11: =E11-G11 -> 0.7708
C12: =+C11+25 -> 100 | D12: 155 | E12: 167.183 | F12: 8.3882 | G12: =D12+F12 -> 163.3882 | H12: =E12-G12 -> 3.7948
C13: =+C12+25 -> 125 | D13: 155 | E13: 168.06 | F13: 8.2326 | G13: =D13+F13 -> 163.2326 | H13: =E13-G13 -> 4.8274
C14: =+C13+25 -> 150 | D14: 155 | E14: 168.76 | F14: 8.0767 | G14: =D14+F14 -> 163.0767 | H14: =E14-G14 -> 5.6833
C15: =+C14+25 -> 175 | D15: 155 | E15: 169.177 | F15: 7.9209 | G15: =D15+F15 -> 162.9209 | H15: =E15-G15 -> 6.2561
C16: =+C15+25 -> 200 | D16: 155 | E16: 169.954 | F16: 7.7651 | G16: =D16+F16 -> 162.7651 | H16: =E16-G16 -> 7.1889
C17: =+C16+25 -> 225 | D17: 155 | E17: 171.118 | F17: 7.6093 | G17: =D17+F17 -> 162.6093 | H17: =E17-G17 -> 8.5087
C18: =+C17+25 -> 250 | D18: 155 | E18: 172.734 | F18: 7.4535 | G18: =D18+F18 -> 162.4535 | H18: =E18-G18 -> 10.2805
C19: =+C18+25 -> 275 | D19: 155 | E19: 175.764 | F19: 7.3415 | G19: =D19+F19 -> 162.3415 | H19: =E19-G19 -> 13.4225
C20: =+C19+25 -> 300 | D20: 155 | E20: 179.256 | F20: 7.1418 | G20: =D20+F20 -> 162.1418 | H20: =E20-G20 -> 17.1142
C21: =+C20+25 -> 325 | D21: 155 | E21: 183.62 | F21: 6.986 | G21: =D21+F21 -> 161.986 | H21: =E21-G21 -> 21.634
... C26: =+C25+25 -> 450 | D26: 155 | E26: 195.79 | F26: 6.207 | G26: =D26+F26 -> 161.207 | H26: =E26-G26 -> 34.583
C27: =+C26+25 -> 475 | D27: 155 | E27: 195.04 | F27: 6.0512 | G27: =D27+F27 -> 161.0512 | H27: =E27-G27 -> 33.9888 | J27: catatan hasil survey masuk ke punden
C28: =+C27+25 -> 500 | D28: 155 | E28: 191.347 | F28: 5.8953 | G28: =D28+F28 -> 160.8953 | H28: =E28-G28 -> 30.4517
C29: =+C28+25 -> 525 | D29: 155 | E29: 187.376 | F29: 5.7394 | G29: =D29+F29 -> 160.7394 | H29: =E29-G29 -> 26.6366
C30: =+C29+25 -> 550 | D30: 155 | E30: 184.632 | F30: 5.5836 | G30: =D30+F30 -> 160.5836 | H30: =E30-G30 -> 24.0484
C31: =+C30+25 -> 575 | D31: 155 | E31: 183.602 | F31: 5.4278 | G31: =D31+F31 -> 160.4278 | H31: =E31-G31 -> 23.1742
C32: =+C31+25 -> 600 | D32: 155 | E32: 182.729 | F32: 5.272 | G32: =D32+F32 -> 160.272 | H32: =E32-G32 -> 22.457
C33: =+C32+25 -> 625 | D33: 155 | E33: 177.313 | F33: 5.1162 | G33: =D33+F33 -> 160.1162 | H33: =E33-G33 -> 17.1968
C34: =+C33+25 -> 650 | D34: 155 | E34: 169.846 | F34: 4.9605 | G34: =D34+F34 -> 159.9605 | H34: =E34-G34 -> 9.8855
C35: =+C34+25 -> 675 | D35: 155 | E35: 167.561 | F35: 4.8047 | G35: =D35+F35 -> 159.8047 | H35: =E35-G35 -> 7.7563
C36: =+C35+25 -> 700 | D36: 155 | E36: 165.744 | F36: 4.6488 | G36: =D36+F36 -> 159.6488 | H36: =E36-G36 -> 6.0952
C37: =+C36+25 -> 725 | D37: 155 | E37: 162.2 | F37: 4.493 | G37: =D37+F37 -> 159.493 | H37: =E37-G37 -> 2.707
C38: =+C37+25 -> 750 | D38: 155 | E38: 161.657 | F38: 4.3372 | G38: =D38+F38 -> 159.3372 | H38: =E38-G38 -> 2.3198
C39: =+C38+25 -> 775 | D39: 155 | E39: 161.38 | F39: 4.1814 | G39: =D39+F39 -> 159.1814 | H39: =E39-G39 -> 2.1986
... C53: =+C52+25 -> 1125 | D53: 155 | E53: 157.238 | F53: 2 | G53: =D53+F53 -> 157 | H53: =E53-G53 -> 0.238
C54: =+C53+25 -> 1150 | D54: 155 | E54: 159.94
